[2024-04-23T16:44:29.486+0000] {local_task_job_runner.py:120} INFO - ::group::Pre task execution logs
[2024-04-23T16:44:29.508+0000] {taskinstance.py:2073} INFO - Dependencies all met for dep_context=non-requeueable deps ti=<TaskInstance: daily_task_dag.load_warehouse manual__2024-04-23T16:43:50.337132+00:00 [queued]>
[2024-04-23T16:44:29.514+0000] {taskinstance.py:2073} INFO - Dependencies all met for dep_context=requeueable deps ti=<TaskInstance: daily_task_dag.load_warehouse manual__2024-04-23T16:43:50.337132+00:00 [queued]>
[2024-04-23T16:44:29.514+0000] {taskinstance.py:2303} INFO - Starting attempt 1 of 2
[2024-04-23T16:44:29.526+0000] {taskinstance.py:2327} INFO - Executing <Task(PythonOperator): load_warehouse> on 2024-04-23 16:43:50.337132+00:00
[2024-04-23T16:44:29.536+0000] {standard_task_runner.py:90} INFO - Running: ['***', 'tasks', 'run', 'daily_task_dag', 'load_warehouse', 'manual__2024-04-23T16:43:50.337132+00:00', '--job-id', '5', '--raw', '--subdir', 'DAGS_FOLDER/DataMLOps.py', '--cfg-path', '/tmp/tmpdwbv33ah']
[2024-04-23T16:44:29.538+0000] {standard_task_runner.py:91} INFO - Job 5: Subtask load_warehouse
[2024-04-23T16:44:29.539+0000] {logging_mixin.py:188} WARNING - /home/***/.local/lib/python3.12/site-packages/***/task/task_runner/standard_task_runner.py:61 DeprecationWarning: This process (pid=381) is multi-threaded, use of fork() may lead to deadlocks in the child.
[2024-04-23T16:44:29.540+0000] {standard_task_runner.py:63} INFO - Started process 394 to run task
[2024-04-23T16:44:29.575+0000] {task_command.py:426} INFO - Running <TaskInstance: daily_task_dag.load_warehouse manual__2024-04-23T16:43:50.337132+00:00 [running]> on host 5ee87de5b592
[2024-04-23T16:44:29.636+0000] {taskinstance.py:2644} INFO - Exporting env vars: AIRFLOW_CTX_DAG_OWNER='***' AIRFLOW_CTX_DAG_ID='daily_task_dag' AIRFLOW_CTX_TASK_ID='load_warehouse' AIRFLOW_CTX_EXECUTION_DATE='2024-04-23T16:43:50.337132+00:00' AIRFLOW_CTX_TRY_NUMBER='1' AIRFLOW_CTX_DAG_RUN_ID='manual__2024-04-23T16:43:50.337132+00:00'
[2024-04-23T16:44:29.637+0000] {taskinstance.py:430} INFO - ::endgroup::
[2024-04-23T16:44:29.775+0000] {logging_mixin.py:188} INFO - Database 'bt4301_gp_datawarehouse' already exists. No need to create it.
[2024-04-23T16:44:29.782+0000] {logging_mixin.py:188} INFO - MySQL connection is closed
[2024-04-23T16:44:30.029+0000] {taskinstance.py:441} INFO - ::group::Post task execution logs
[2024-04-23T16:44:30.030+0000] {taskinstance.py:2890} ERROR - Task failed with exception
Traceback (most recent call last):
  File "/home/airflow/.local/lib/python3.12/site-packages/airflow/models/taskinstance.py", line 465, in _execute_task
    result = _execute_callable(context=context, **execute_callable_kwargs)
             ^^^^^^^^^^^^^^^^^^^^^^^^^^^^^^^^^^^^^^^^^^^^^^^^^^^^^^^^^^^^^
  File "/home/airflow/.local/lib/python3.12/site-packages/airflow/models/taskinstance.py", line 432, in _execute_callable
    return execute_callable(context=context, **execute_callable_kwargs)
           ^^^^^^^^^^^^^^^^^^^^^^^^^^^^^^^^^^^^^^^^^^^^^^^^^^^^^^^^^^^^
  File "/home/airflow/.local/lib/python3.12/site-packages/airflow/models/baseoperator.py", line 400, in wrapper
    return func(self, *args, **kwargs)
           ^^^^^^^^^^^^^^^^^^^^^^^^^^^
  File "/home/airflow/.local/lib/python3.12/site-packages/airflow/operators/python.py", line 235, in execute
    return_value = self.execute_callable()
                   ^^^^^^^^^^^^^^^^^^^^^^^
  File "/home/airflow/.local/lib/python3.12/site-packages/airflow/operators/python.py", line 252, in execute_callable
    return self.python_callable(*self.op_args, **self.op_kwargs)
           ^^^^^^^^^^^^^^^^^^^^^^^^^^^^^^^^^^^^^^^^^^^^^^^^^^^^^
  File "/opt/airflow/dags/DataMLOps.py", line 264, in load_warehouse
    client = storage.Client.from_service_account_json(json_credentials_path=path_to_private_key)
             ^^^^^^^^^^^^^^^^^^^^^^^^^^^^^^^^^^^^^^^^^^^^^^^^^^^^^^^^^^^^^^^^^^^^^^^^^^^^^^^^^^^
  File "/home/airflow/.local/lib/python3.12/site-packages/google/cloud/client/__init__.py", line 106, in from_service_account_json
    with io.open(json_credentials_path, "r", encoding="utf-8") as json_fi:
         ^^^^^^^^^^^^^^^^^^^^^^^^^^^^^^^^^^^^^^^^^^^^^^^^^^^^^
FileNotFoundError: [Errno 2] No such file or directory: 'ethereal-anthem-417503-1d749c7332fa.json'
[2024-04-23T16:44:30.039+0000] {taskinstance.py:1205} INFO - Marking task as UP_FOR_RETRY. dag_id=daily_task_dag, task_id=load_warehouse, execution_date=20240423T164350, start_date=20240423T164429, end_date=20240423T164430
[2024-04-23T16:44:30.049+0000] {standard_task_runner.py:110} ERROR - Failed to execute job 5 for task load_warehouse ([Errno 2] No such file or directory: 'ethereal-anthem-417503-1d749c7332fa.json'; 394)
[2024-04-23T16:44:30.074+0000] {local_task_job_runner.py:240} INFO - Task exited with return code 1
[2024-04-23T16:44:30.089+0000] {taskinstance.py:3482} INFO - 0 downstream tasks scheduled from follow-on schedule check
[2024-04-23T16:44:30.095+0000] {local_task_job_runner.py:222} INFO - ::endgroup::
