[2024-04-23T15:05:55.527+0000] {local_task_job_runner.py:120} INFO - ::group::Pre task execution logs
[2024-04-23T15:05:55.554+0000] {taskinstance.py:2073} INFO - Dependencies all met for dep_context=non-requeueable deps ti=<TaskInstance: daily_task_dag.task_2 manual__2024-04-23T14:59:48.335967+00:00 [queued]>
[2024-04-23T15:05:55.561+0000] {taskinstance.py:2073} INFO - Dependencies all met for dep_context=requeueable deps ti=<TaskInstance: daily_task_dag.task_2 manual__2024-04-23T14:59:48.335967+00:00 [queued]>
[2024-04-23T15:05:55.562+0000] {taskinstance.py:2303} INFO - Starting attempt 2 of 2
[2024-04-23T15:05:55.576+0000] {taskinstance.py:2327} INFO - Executing <Task(PythonOperator): task_2> on 2024-04-23 14:59:48.335967+00:00
[2024-04-23T15:05:55.587+0000] {standard_task_runner.py:90} INFO - Running: ['***', 'tasks', 'run', 'daily_task_dag', 'task_2', 'manual__2024-04-23T14:59:48.335967+00:00', '--job-id', '4', '--raw', '--subdir', 'DAGS_FOLDER/DataMLOps.py', '--cfg-path', '/tmp/tmppm0v88ja']
[2024-04-23T15:05:55.589+0000] {standard_task_runner.py:91} INFO - Job 4: Subtask task_2
[2024-04-23T15:05:55.590+0000] {logging_mixin.py:188} WARNING - /home/***/.local/lib/python3.12/site-packages/***/task/task_runner/standard_task_runner.py:61 DeprecationWarning: This process (pid=566) is multi-threaded, use of fork() may lead to deadlocks in the child.
[2024-04-23T15:05:55.591+0000] {standard_task_runner.py:63} INFO - Started process 579 to run task
[2024-04-23T15:05:55.631+0000] {task_command.py:426} INFO - Running <TaskInstance: daily_task_dag.task_2 manual__2024-04-23T14:59:48.335967+00:00 [running]> on host 21330f56d46c
[2024-04-23T15:05:55.867+0000] {taskinstance.py:2644} INFO - Exporting env vars: AIRFLOW_CTX_DAG_OWNER='***' AIRFLOW_CTX_DAG_ID='daily_task_dag' AIRFLOW_CTX_TASK_ID='task_2' AIRFLOW_CTX_EXECUTION_DATE='2024-04-23T14:59:48.335967+00:00' AIRFLOW_CTX_TRY_NUMBER='2' AIRFLOW_CTX_DAG_RUN_ID='manual__2024-04-23T14:59:48.335967+00:00'
[2024-04-23T15:05:55.868+0000] {taskinstance.py:430} INFO - ::endgroup::
[2024-04-23T15:05:55.888+0000] {logging_mixin.py:188} INFO - Loading URI
[2024-04-23T15:05:55.889+0000] {logging_mixin.py:188} INFO - Finish Loading URI, loading model
[2024-04-23T15:05:55.926+0000] {connectionpool.py:824} WARNING - Retrying (JitteredRetry(total=4, connect=4, read=5, redirect=5, status=5)) after connection broken by 'NewConnectionError('<urllib3.connection.HTTPConnection object at 0x7fa6991798e0>: Failed to establish a new connection: [Errno 111] Connection refused')': /api/2.0/mlflow/runs/get?run_uuid=0ad62ab3a0754013a65ce4bc703eed9a&run_id=0ad62ab3a0754013a65ce4bc703eed9a
[2024-04-23T15:05:59.927+0000] {connectionpool.py:824} WARNING - Retrying (JitteredRetry(total=3, connect=3, read=5, redirect=5, status=5)) after connection broken by 'NewConnectionError('<urllib3.connection.HTTPConnection object at 0x7fa699196630>: Failed to establish a new connection: [Errno 111] Connection refused')': /api/2.0/mlflow/runs/get?run_uuid=0ad62ab3a0754013a65ce4bc703eed9a&run_id=0ad62ab3a0754013a65ce4bc703eed9a
[2024-04-23T15:06:07.929+0000] {connectionpool.py:824} WARNING - Retrying (JitteredRetry(total=2, connect=2, read=5, redirect=5, status=5)) after connection broken by 'NewConnectionError('<urllib3.connection.HTTPConnection object at 0x7fa699197a40>: Failed to establish a new connection: [Errno 111] Connection refused')': /api/2.0/mlflow/runs/get?run_uuid=0ad62ab3a0754013a65ce4bc703eed9a&run_id=0ad62ab3a0754013a65ce4bc703eed9a
[2024-04-23T15:06:23.929+0000] {connectionpool.py:824} WARNING - Retrying (JitteredRetry(total=1, connect=1, read=5, redirect=5, status=5)) after connection broken by 'NewConnectionError('<urllib3.connection.HTTPConnection object at 0x7fa6991956a0>: Failed to establish a new connection: [Errno 111] Connection refused')': /api/2.0/mlflow/runs/get?run_uuid=0ad62ab3a0754013a65ce4bc703eed9a&run_id=0ad62ab3a0754013a65ce4bc703eed9a
[2024-04-23T15:06:55.929+0000] {connectionpool.py:824} WARNING - Retrying (JitteredRetry(total=0, connect=0, read=5, redirect=5, status=5)) after connection broken by 'NewConnectionError('<urllib3.connection.HTTPConnection object at 0x7fa6991d0f20>: Failed to establish a new connection: [Errno 111] Connection refused')': /api/2.0/mlflow/runs/get?run_uuid=0ad62ab3a0754013a65ce4bc703eed9a&run_id=0ad62ab3a0754013a65ce4bc703eed9a
[2024-04-23T15:06:55.931+0000] {taskinstance.py:441} INFO - ::group::Post task execution logs
[2024-04-23T15:06:55.931+0000] {taskinstance.py:2890} ERROR - Task failed with exception
Traceback (most recent call last):
  File "/home/airflow/.local/lib/python3.12/site-packages/urllib3/connection.py", line 174, in _new_conn
    conn = connection.create_connection(
           ^^^^^^^^^^^^^^^^^^^^^^^^^^^^^
  File "/home/airflow/.local/lib/python3.12/site-packages/urllib3/util/connection.py", line 95, in create_connection
    raise err
  File "/home/airflow/.local/lib/python3.12/site-packages/urllib3/util/connection.py", line 85, in create_connection
    sock.connect(sa)
ConnectionRefusedError: [Errno 111] Connection refused

During handling of the above exception, another exception occurred:

Traceback (most recent call last):
  File "/home/airflow/.local/lib/python3.12/site-packages/urllib3/connectionpool.py", line 715, in urlopen
    httplib_response = self._make_request(
                       ^^^^^^^^^^^^^^^^^^^
  File "/home/airflow/.local/lib/python3.12/site-packages/urllib3/connectionpool.py", line 416, in _make_request
    conn.request(method, url, **httplib_request_kw)
  File "/home/airflow/.local/lib/python3.12/site-packages/urllib3/connection.py", line 244, in request
    super(HTTPConnection, self).request(method, url, body=body, headers=headers)
  File "/usr/local/lib/python3.12/http/client.py", line 1331, in request
    self._send_request(method, url, body, headers, encode_chunked)
  File "/usr/local/lib/python3.12/http/client.py", line 1377, in _send_request
    self.endheaders(body, encode_chunked=encode_chunked)
  File "/usr/local/lib/python3.12/http/client.py", line 1326, in endheaders
    self._send_output(message_body, encode_chunked=encode_chunked)
  File "/usr/local/lib/python3.12/http/client.py", line 1085, in _send_output
    self.send(msg)
  File "/usr/local/lib/python3.12/http/client.py", line 1029, in send
    self.connect()
  File "/home/airflow/.local/lib/python3.12/site-packages/urllib3/connection.py", line 205, in connect
    conn = self._new_conn()
           ^^^^^^^^^^^^^^^^
  File "/home/airflow/.local/lib/python3.12/site-packages/urllib3/connection.py", line 186, in _new_conn
    raise NewConnectionError(
urllib3.exceptions.NewConnectionError: <urllib3.connection.HTTPConnection object at 0x7fa6991d2060>: Failed to establish a new connection: [Errno 111] Connection refused

During handling of the above exception, another exception occurred:

Traceback (most recent call last):
  File "/home/airflow/.local/lib/python3.12/site-packages/requests/adapters.py", line 486, in send
    resp = conn.urlopen(
           ^^^^^^^^^^^^^
  File "/home/airflow/.local/lib/python3.12/site-packages/urllib3/connectionpool.py", line 827, in urlopen
    return self.urlopen(
           ^^^^^^^^^^^^^
  File "/home/airflow/.local/lib/python3.12/site-packages/urllib3/connectionpool.py", line 827, in urlopen
    return self.urlopen(
           ^^^^^^^^^^^^^
  File "/home/airflow/.local/lib/python3.12/site-packages/urllib3/connectionpool.py", line 827, in urlopen
    return self.urlopen(
           ^^^^^^^^^^^^^
  [Previous line repeated 2 more times]
  File "/home/airflow/.local/lib/python3.12/site-packages/urllib3/connectionpool.py", line 799, in urlopen
    retries = retries.increment(
              ^^^^^^^^^^^^^^^^^^
  File "/home/airflow/.local/lib/python3.12/site-packages/urllib3/util/retry.py", line 592, in increment
    raise MaxRetryError(_pool, url, error or ResponseError(cause))
urllib3.exceptions.MaxRetryError: HTTPConnectionPool(host='localhost', port=9080): Max retries exceeded with url: /api/2.0/mlflow/runs/get?run_uuid=0ad62ab3a0754013a65ce4bc703eed9a&run_id=0ad62ab3a0754013a65ce4bc703eed9a (Caused by NewConnectionError('<urllib3.connection.HTTPConnection object at 0x7fa6991d2060>: Failed to establish a new connection: [Errno 111] Connection refused'))

During handling of the above exception, another exception occurred:

Traceback (most recent call last):
  File "/home/airflow/.local/lib/python3.12/site-packages/mlflow/utils/rest_utils.py", line 128, in http_request
    return _get_http_response_with_retries(
           ^^^^^^^^^^^^^^^^^^^^^^^^^^^^^^^^
  File "/home/airflow/.local/lib/python3.12/site-packages/mlflow/utils/request_utils.py", line 228, in _get_http_response_with_retries
    return session.request(method, url, allow_redirects=allow_redirects, **kwargs)
           ^^^^^^^^^^^^^^^^^^^^^^^^^^^^^^^^^^^^^^^^^^^^^^^^^^^^^^^^^^^^^^^^^^^^^^^
  File "/home/airflow/.local/lib/python3.12/site-packages/requests/sessions.py", line 589, in request
    resp = self.send(prep, **send_kwargs)
           ^^^^^^^^^^^^^^^^^^^^^^^^^^^^^^
  File "/home/airflow/.local/lib/python3.12/site-packages/requests/sessions.py", line 703, in send
    r = adapter.send(request, **kwargs)
        ^^^^^^^^^^^^^^^^^^^^^^^^^^^^^^^
  File "/home/airflow/.local/lib/python3.12/site-packages/requests/adapters.py", line 519, in send
    raise ConnectionError(e, request=request)
requests.exceptions.ConnectionError: HTTPConnectionPool(host='localhost', port=9080): Max retries exceeded with url: /api/2.0/mlflow/runs/get?run_uuid=0ad62ab3a0754013a65ce4bc703eed9a&run_id=0ad62ab3a0754013a65ce4bc703eed9a (Caused by NewConnectionError('<urllib3.connection.HTTPConnection object at 0x7fa6991d2060>: Failed to establish a new connection: [Errno 111] Connection refused'))

During handling of the above exception, another exception occurred:

Traceback (most recent call last):
  File "/home/airflow/.local/lib/python3.12/site-packages/airflow/models/taskinstance.py", line 465, in _execute_task
    result = _execute_callable(context=context, **execute_callable_kwargs)
             ^^^^^^^^^^^^^^^^^^^^^^^^^^^^^^^^^^^^^^^^^^^^^^^^^^^^^^^^^^^^^
  File "/home/airflow/.local/lib/python3.12/site-packages/airflow/models/taskinstance.py", line 432, in _execute_callable
    return execute_callable(context=context, **execute_callable_kwargs)
           ^^^^^^^^^^^^^^^^^^^^^^^^^^^^^^^^^^^^^^^^^^^^^^^^^^^^^^^^^^^^
  File "/home/airflow/.local/lib/python3.12/site-packages/airflow/models/baseoperator.py", line 400, in wrapper
    return func(self, *args, **kwargs)
           ^^^^^^^^^^^^^^^^^^^^^^^^^^^
  File "/home/airflow/.local/lib/python3.12/site-packages/airflow/operators/python.py", line 235, in execute
    return_value = self.execute_callable()
                   ^^^^^^^^^^^^^^^^^^^^^^^
  File "/home/airflow/.local/lib/python3.12/site-packages/airflow/operators/python.py", line 252, in execute_callable
    return self.python_callable(*self.op_args, **self.op_kwargs)
           ^^^^^^^^^^^^^^^^^^^^^^^^^^^^^^^^^^^^^^^^^^^^^^^^^^^^^
  File "/opt/airflow/dags/DataMLOps.py", line 27, in print_hello
    loaded_model = mlflow.pyfunc.load_model('runs:/0ad62ab3a0754013a65ce4bc703eed9a/baseline_model')
                   ^^^^^^^^^^^^^^^^^^^^^^^^^^^^^^^^^^^^^^^^^^^^^^^^^^^^^^^^^^^^^^^^^^^^^^^^^^^^^^^^^
  File "/home/airflow/.local/lib/python3.12/site-packages/mlflow/pyfunc/__init__.py", line 864, in load_model
    local_path = _download_artifact_from_uri(artifact_uri=model_uri, output_path=dst_path)
                 ^^^^^^^^^^^^^^^^^^^^^^^^^^^^^^^^^^^^^^^^^^^^^^^^^^^^^^^^^^^^^^^^^^^^^^^^^
  File "/home/airflow/.local/lib/python3.12/site-packages/mlflow/tracking/artifact_utils.py", line 106, in _download_artifact_from_uri
    return get_artifact_repository(artifact_uri=root_uri).download_artifacts(
           ^^^^^^^^^^^^^^^^^^^^^^^^^^^^^^^^^^^^^^^^^^^^^^
  File "/home/airflow/.local/lib/python3.12/site-packages/mlflow/store/artifact/artifact_repository_registry.py", line 124, in get_artifact_repository
    return _artifact_repository_registry.get_artifact_repository(artifact_uri)
           ^^^^^^^^^^^^^^^^^^^^^^^^^^^^^^^^^^^^^^^^^^^^^^^^^^^^^^^^^^^^^^^^^^^
  File "/home/airflow/.local/lib/python3.12/site-packages/mlflow/store/artifact/artifact_repository_registry.py", line 77, in get_artifact_repository
    return repository(artifact_uri)
           ^^^^^^^^^^^^^^^^^^^^^^^^
  File "/home/airflow/.local/lib/python3.12/site-packages/mlflow/store/artifact/runs_artifact_repo.py", line 26, in __init__
    uri = RunsArtifactRepository.get_underlying_uri(artifact_uri)
          ^^^^^^^^^^^^^^^^^^^^^^^^^^^^^^^^^^^^^^^^^^^^^^^^^^^^^^^
  File "/home/airflow/.local/lib/python3.12/site-packages/mlflow/store/artifact/runs_artifact_repo.py", line 39, in get_underlying_uri
    uri = get_artifact_uri(run_id, artifact_path, tracking_uri)
          ^^^^^^^^^^^^^^^^^^^^^^^^^^^^^^^^^^^^^^^^^^^^^^^^^^^^^
  File "/home/airflow/.local/lib/python3.12/site-packages/mlflow/tracking/artifact_utils.py", line 51, in get_artifact_uri
    run = store.get_run(run_id)
          ^^^^^^^^^^^^^^^^^^^^^
  File "/home/airflow/.local/lib/python3.12/site-packages/mlflow/store/tracking/rest_store.py", line 144, in get_run
    response_proto = self._call_endpoint(GetRun, req_body)
                     ^^^^^^^^^^^^^^^^^^^^^^^^^^^^^^^^^^^^^
  File "/home/airflow/.local/lib/python3.12/site-packages/mlflow/store/tracking/rest_store.py", line 60, in _call_endpoint
    return call_endpoint(self.get_host_creds(), endpoint, method, json_body, response_proto)
           ^^^^^^^^^^^^^^^^^^^^^^^^^^^^^^^^^^^^^^^^^^^^^^^^^^^^^^^^^^^^^^^^^^^^^^^^^^^^^^^^^
  File "/home/airflow/.local/lib/python3.12/site-packages/mlflow/utils/rest_utils.py", line 286, in call_endpoint
    response = http_request(**call_kwargs)
               ^^^^^^^^^^^^^^^^^^^^^^^^^^^
  File "/home/airflow/.local/lib/python3.12/site-packages/mlflow/utils/rest_utils.py", line 151, in http_request
    raise MlflowException(f"API request to {url} failed with exception {e}")
mlflow.exceptions.MlflowException: API request to http://localhost:9080/api/2.0/mlflow/runs/get failed with exception HTTPConnectionPool(host='localhost', port=9080): Max retries exceeded with url: /api/2.0/mlflow/runs/get?run_uuid=0ad62ab3a0754013a65ce4bc703eed9a&run_id=0ad62ab3a0754013a65ce4bc703eed9a (Caused by NewConnectionError('<urllib3.connection.HTTPConnection object at 0x7fa6991d2060>: Failed to establish a new connection: [Errno 111] Connection refused'))
[2024-04-23T15:06:55.946+0000] {taskinstance.py:1205} INFO - Marking task as FAILED. dag_id=daily_task_dag, task_id=task_2, execution_date=20240423T145948, start_date=20240423T150555, end_date=20240423T150655
[2024-04-23T15:06:55.957+0000] {standard_task_runner.py:110} ERROR - Failed to execute job 4 for task task_2 (API request to http://localhost:9080/api/2.0/mlflow/runs/get failed with exception HTTPConnectionPool(host='localhost', port=9080): Max retries exceeded with url: /api/2.0/mlflow/runs/get?run_uuid=0ad62ab3a0754013a65ce4bc703eed9a&run_id=0ad62ab3a0754013a65ce4bc703eed9a (Caused by NewConnectionError('<urllib3.connection.HTTPConnection object at 0x7fa6991d2060>: Failed to establish a new connection: [Errno 111] Connection refused')); 579)
[2024-04-23T15:06:56.006+0000] {local_task_job_runner.py:240} INFO - Task exited with return code 1
[2024-04-23T15:06:56.025+0000] {taskinstance.py:3482} INFO - 0 downstream tasks scheduled from follow-on schedule check
[2024-04-23T15:06:56.030+0000] {local_task_job_runner.py:222} INFO - ::endgroup::
