[2024-04-23T15:07:57.616+0000] {local_task_job_runner.py:120} INFO - ::group::Pre task execution logs
[2024-04-23T15:07:57.640+0000] {taskinstance.py:2073} INFO - Dependencies all met for dep_context=non-requeueable deps ti=<TaskInstance: daily_task_dag.task_2 manual__2024-04-23T15:07:55.937738+00:00 [queued]>
[2024-04-23T15:07:57.647+0000] {taskinstance.py:2073} INFO - Dependencies all met for dep_context=requeueable deps ti=<TaskInstance: daily_task_dag.task_2 manual__2024-04-23T15:07:55.937738+00:00 [queued]>
[2024-04-23T15:07:57.648+0000] {taskinstance.py:2303} INFO - Starting attempt 1 of 2
[2024-04-23T15:07:57.660+0000] {taskinstance.py:2327} INFO - Executing <Task(PythonOperator): task_2> on 2024-04-23 15:07:55.937738+00:00
[2024-04-23T15:07:57.668+0000] {standard_task_runner.py:90} INFO - Running: ['***', 'tasks', 'run', 'daily_task_dag', 'task_2', 'manual__2024-04-23T15:07:55.937738+00:00', '--job-id', '5', '--raw', '--subdir', 'DAGS_FOLDER/DataMLOps.py', '--cfg-path', '/tmp/tmpko8ep5t4']
[2024-04-23T15:07:57.669+0000] {standard_task_runner.py:91} INFO - Job 5: Subtask task_2
[2024-04-23T15:07:57.671+0000] {logging_mixin.py:188} WARNING - /home/***/.local/lib/python3.12/site-packages/***/task/task_runner/standard_task_runner.py:61 DeprecationWarning: This process (pid=672) is multi-threaded, use of fork() may lead to deadlocks in the child.
[2024-04-23T15:07:57.672+0000] {standard_task_runner.py:63} INFO - Started process 685 to run task
[2024-04-23T15:07:57.707+0000] {task_command.py:426} INFO - Running <TaskInstance: daily_task_dag.task_2 manual__2024-04-23T15:07:55.937738+00:00 [running]> on host 21330f56d46c
[2024-04-23T15:07:57.916+0000] {taskinstance.py:2644} INFO - Exporting env vars: AIRFLOW_CTX_DAG_OWNER='***' AIRFLOW_CTX_DAG_ID='daily_task_dag' AIRFLOW_CTX_TASK_ID='task_2' AIRFLOW_CTX_EXECUTION_DATE='2024-04-23T15:07:55.937738+00:00' AIRFLOW_CTX_TRY_NUMBER='1' AIRFLOW_CTX_DAG_RUN_ID='manual__2024-04-23T15:07:55.937738+00:00'
[2024-04-23T15:07:57.917+0000] {taskinstance.py:430} INFO - ::endgroup::
[2024-04-23T15:07:57.937+0000] {taskinstance.py:441} INFO - ::group::Post task execution logs
[2024-04-23T15:07:57.938+0000] {taskinstance.py:2890} ERROR - Task failed with exception
Traceback (most recent call last):
  File "/home/airflow/.local/lib/python3.12/site-packages/airflow/models/taskinstance.py", line 465, in _execute_task
    result = _execute_callable(context=context, **execute_callable_kwargs)
             ^^^^^^^^^^^^^^^^^^^^^^^^^^^^^^^^^^^^^^^^^^^^^^^^^^^^^^^^^^^^^
  File "/home/airflow/.local/lib/python3.12/site-packages/airflow/models/taskinstance.py", line 432, in _execute_callable
    return execute_callable(context=context, **execute_callable_kwargs)
           ^^^^^^^^^^^^^^^^^^^^^^^^^^^^^^^^^^^^^^^^^^^^^^^^^^^^^^^^^^^^
  File "/home/airflow/.local/lib/python3.12/site-packages/airflow/models/baseoperator.py", line 400, in wrapper
    return func(self, *args, **kwargs)
           ^^^^^^^^^^^^^^^^^^^^^^^^^^^
  File "/home/airflow/.local/lib/python3.12/site-packages/airflow/operators/python.py", line 235, in execute
    return_value = self.execute_callable()
                   ^^^^^^^^^^^^^^^^^^^^^^^
  File "/home/airflow/.local/lib/python3.12/site-packages/airflow/operators/python.py", line 252, in execute_callable
    return self.python_callable(*self.op_args, **self.op_kwargs)
           ^^^^^^^^^^^^^^^^^^^^^^^^^^^^^^^^^^^^^^^^^^^^^^^^^^^^^
  File "/opt/airflow/dags/DataMLOps.py", line 30, in print_hello
    with open('your_model.pkl', 'rb') as file:
         ^^^^^^^^^^^^^^^^^^^^^^^^^^^^
FileNotFoundError: [Errno 2] No such file or directory: 'your_model.pkl'
[2024-04-23T15:07:57.949+0000] {taskinstance.py:1205} INFO - Marking task as UP_FOR_RETRY. dag_id=daily_task_dag, task_id=task_2, execution_date=20240423T150755, start_date=20240423T150757, end_date=20240423T150757
[2024-04-23T15:07:57.966+0000] {standard_task_runner.py:110} ERROR - Failed to execute job 5 for task task_2 ([Errno 2] No such file or directory: 'your_model.pkl'; 685)
[2024-04-23T15:07:58.006+0000] {local_task_job_runner.py:240} INFO - Task exited with return code 1
[2024-04-23T15:07:58.034+0000] {taskinstance.py:3482} INFO - 0 downstream tasks scheduled from follow-on schedule check
[2024-04-23T15:07:58.040+0000] {local_task_job_runner.py:222} INFO - ::endgroup::
