[2024-04-23T15:08:27.575+0000] {local_task_job_runner.py:120} INFO - ::group::Pre task execution logs
[2024-04-23T15:08:27.600+0000] {taskinstance.py:2073} INFO - Dependencies all met for dep_context=non-requeueable deps ti=<TaskInstance: daily_task_dag.task_2 manual__2024-04-23T15:08:25.545610+00:00 [queued]>
[2024-04-23T15:08:27.607+0000] {taskinstance.py:2073} INFO - Dependencies all met for dep_context=requeueable deps ti=<TaskInstance: daily_task_dag.task_2 manual__2024-04-23T15:08:25.545610+00:00 [queued]>
[2024-04-23T15:08:27.608+0000] {taskinstance.py:2303} INFO - Starting attempt 1 of 2
[2024-04-23T15:08:27.622+0000] {taskinstance.py:2327} INFO - Executing <Task(PythonOperator): task_2> on 2024-04-23 15:08:25.545610+00:00
[2024-04-23T15:08:27.630+0000] {standard_task_runner.py:90} INFO - Running: ['***', 'tasks', 'run', 'daily_task_dag', 'task_2', 'manual__2024-04-23T15:08:25.545610+00:00', '--job-id', '6', '--raw', '--subdir', 'DAGS_FOLDER/DataMLOps.py', '--cfg-path', '/tmp/tmpd42e04mr']
[2024-04-23T15:08:27.632+0000] {standard_task_runner.py:91} INFO - Job 6: Subtask task_2
[2024-04-23T15:08:27.634+0000] {logging_mixin.py:188} WARNING - /home/***/.local/lib/python3.12/site-packages/***/task/task_runner/standard_task_runner.py:61 DeprecationWarning: This process (pid=726) is multi-threaded, use of fork() may lead to deadlocks in the child.
[2024-04-23T15:08:27.634+0000] {standard_task_runner.py:63} INFO - Started process 739 to run task
[2024-04-23T15:08:27.669+0000] {task_command.py:426} INFO - Running <TaskInstance: daily_task_dag.task_2 manual__2024-04-23T15:08:25.545610+00:00 [running]> on host 21330f56d46c
[2024-04-23T15:08:27.882+0000] {taskinstance.py:2644} INFO - Exporting env vars: AIRFLOW_CTX_DAG_OWNER='***' AIRFLOW_CTX_DAG_ID='daily_task_dag' AIRFLOW_CTX_TASK_ID='task_2' AIRFLOW_CTX_EXECUTION_DATE='2024-04-23T15:08:25.545610+00:00' AIRFLOW_CTX_TRY_NUMBER='1' AIRFLOW_CTX_DAG_RUN_ID='manual__2024-04-23T15:08:25.545610+00:00'
[2024-04-23T15:08:27.883+0000] {taskinstance.py:430} INFO - ::endgroup::
[2024-04-23T15:08:27.901+0000] {taskinstance.py:441} INFO - ::group::Post task execution logs
[2024-04-23T15:08:27.902+0000] {taskinstance.py:2890} ERROR - Task failed with exception
Traceback (most recent call last):
  File "/home/airflow/.local/lib/python3.12/site-packages/airflow/models/taskinstance.py", line 465, in _execute_task
    result = _execute_callable(context=context, **execute_callable_kwargs)
             ^^^^^^^^^^^^^^^^^^^^^^^^^^^^^^^^^^^^^^^^^^^^^^^^^^^^^^^^^^^^^
  File "/home/airflow/.local/lib/python3.12/site-packages/airflow/models/taskinstance.py", line 432, in _execute_callable
    return execute_callable(context=context, **execute_callable_kwargs)
           ^^^^^^^^^^^^^^^^^^^^^^^^^^^^^^^^^^^^^^^^^^^^^^^^^^^^^^^^^^^^
  File "/home/airflow/.local/lib/python3.12/site-packages/airflow/models/baseoperator.py", line 400, in wrapper
    return func(self, *args, **kwargs)
           ^^^^^^^^^^^^^^^^^^^^^^^^^^^
  File "/home/airflow/.local/lib/python3.12/site-packages/airflow/operators/python.py", line 235, in execute
    return_value = self.execute_callable()
                   ^^^^^^^^^^^^^^^^^^^^^^^
  File "/home/airflow/.local/lib/python3.12/site-packages/airflow/operators/python.py", line 252, in execute_callable
    return self.python_callable(*self.op_args, **self.op_kwargs)
           ^^^^^^^^^^^^^^^^^^^^^^^^^^^^^^^^^^^^^^^^^^^^^^^^^^^^^
  File "/opt/airflow/dags/DataMLOps.py", line 30, in print_hello
    with open('model.pkl', 'rb') as file:
         ^^^^^^^^^^^^^^^^^^^^^^^
FileNotFoundError: [Errno 2] No such file or directory: 'model.pkl'
[2024-04-23T15:08:27.910+0000] {taskinstance.py:1205} INFO - Marking task as UP_FOR_RETRY. dag_id=daily_task_dag, task_id=task_2, execution_date=20240423T150825, start_date=20240423T150827, end_date=20240423T150827
[2024-04-23T15:08:27.921+0000] {standard_task_runner.py:110} ERROR - Failed to execute job 6 for task task_2 ([Errno 2] No such file or directory: 'model.pkl'; 739)
[2024-04-23T15:08:27.968+0000] {local_task_job_runner.py:240} INFO - Task exited with return code 1
[2024-04-23T15:08:27.987+0000] {taskinstance.py:3482} INFO - 0 downstream tasks scheduled from follow-on schedule check
[2024-04-23T15:08:27.991+0000] {local_task_job_runner.py:222} INFO - ::endgroup::
