[2024-04-23T18:11:34.873+0000] {local_task_job_runner.py:120} INFO - ::group::Pre task execution logs
[2024-04-23T18:11:34.894+0000] {taskinstance.py:2073} INFO - Dependencies all met for dep_context=non-requeueable deps ti=<TaskInstance: daily_task_dag.predict_data manual__2024-04-23T18:04:52.305878+00:00 [queued]>
[2024-04-23T18:11:34.900+0000] {taskinstance.py:2073} INFO - Dependencies all met for dep_context=requeueable deps ti=<TaskInstance: daily_task_dag.predict_data manual__2024-04-23T18:04:52.305878+00:00 [queued]>
[2024-04-23T18:11:34.900+0000] {taskinstance.py:2303} INFO - Starting attempt 2 of 2
[2024-04-23T18:11:34.911+0000] {taskinstance.py:2327} INFO - Executing <Task(PythonOperator): predict_data> on 2024-04-23 18:04:52.305878+00:00
[2024-04-23T18:11:34.919+0000] {standard_task_runner.py:90} INFO - Running: ['***', 'tasks', 'run', 'daily_task_dag', 'predict_data', 'manual__2024-04-23T18:04:52.305878+00:00', '--job-id', '6', '--raw', '--subdir', 'DAGS_FOLDER/DataMLOps.py', '--cfg-path', '/tmp/tmpmz64fkzd']
[2024-04-23T18:11:34.921+0000] {standard_task_runner.py:91} INFO - Job 6: Subtask predict_data
[2024-04-23T18:11:34.922+0000] {logging_mixin.py:188} WARNING - /home/***/.local/lib/python3.12/site-packages/***/task/task_runner/standard_task_runner.py:61 DeprecationWarning: This process (pid=603) is multi-threaded, use of fork() may lead to deadlocks in the child.
[2024-04-23T18:11:34.923+0000] {standard_task_runner.py:63} INFO - Started process 618 to run task
[2024-04-23T18:11:34.950+0000] {task_command.py:426} INFO - Running <TaskInstance: daily_task_dag.predict_data manual__2024-04-23T18:04:52.305878+00:00 [running]> on host 24f05fbfe784
[2024-04-23T18:11:35.005+0000] {taskinstance.py:2644} INFO - Exporting env vars: AIRFLOW_CTX_DAG_OWNER='***' AIRFLOW_CTX_DAG_ID='daily_task_dag' AIRFLOW_CTX_TASK_ID='predict_data' AIRFLOW_CTX_EXECUTION_DATE='2024-04-23T18:04:52.305878+00:00' AIRFLOW_CTX_TRY_NUMBER='2' AIRFLOW_CTX_DAG_RUN_ID='manual__2024-04-23T18:04:52.305878+00:00'
[2024-04-23T18:11:35.006+0000] {taskinstance.py:430} INFO - ::endgroup::
[2024-04-23T18:11:35.029+0000] {taskinstance.py:441} INFO - ::group::Post task execution logs
[2024-04-23T18:11:35.029+0000] {taskinstance.py:2890} ERROR - Task failed with exception
Traceback (most recent call last):
  File "/home/airflow/.local/lib/python3.12/site-packages/airflow/models/taskinstance.py", line 465, in _execute_task
    result = _execute_callable(context=context, **execute_callable_kwargs)
             ^^^^^^^^^^^^^^^^^^^^^^^^^^^^^^^^^^^^^^^^^^^^^^^^^^^^^^^^^^^^^
  File "/home/airflow/.local/lib/python3.12/site-packages/airflow/models/taskinstance.py", line 432, in _execute_callable
    return execute_callable(context=context, **execute_callable_kwargs)
           ^^^^^^^^^^^^^^^^^^^^^^^^^^^^^^^^^^^^^^^^^^^^^^^^^^^^^^^^^^^^
  File "/home/airflow/.local/lib/python3.12/site-packages/airflow/models/baseoperator.py", line 400, in wrapper
    return func(self, *args, **kwargs)
           ^^^^^^^^^^^^^^^^^^^^^^^^^^^
  File "/home/airflow/.local/lib/python3.12/site-packages/airflow/operators/python.py", line 235, in execute
    return_value = self.execute_callable()
                   ^^^^^^^^^^^^^^^^^^^^^^^
  File "/home/airflow/.local/lib/python3.12/site-packages/airflow/operators/python.py", line 252, in execute_callable
    return self.python_callable(*self.op_args, **self.op_kwargs)
           ^^^^^^^^^^^^^^^^^^^^^^^^^^^^^^^^^^^^^^^^^^^^^^^^^^^^^
  File "/opt/airflow/dags/DataMLOps.py", line 546, in predict_data
    pickle_in = open('dags/X.pickle',"rb")
                ^^^^^^^^^^^^^^^^^^^^^^^^^^
FileNotFoundError: [Errno 2] No such file or directory: 'dags/X.pickle'
[2024-04-23T18:11:35.038+0000] {taskinstance.py:1205} INFO - Marking task as FAILED. dag_id=daily_task_dag, task_id=predict_data, execution_date=20240423T180452, start_date=20240423T181134, end_date=20240423T181135
[2024-04-23T18:11:35.047+0000] {standard_task_runner.py:110} ERROR - Failed to execute job 6 for task predict_data ([Errno 2] No such file or directory: 'dags/X.pickle'; 618)
[2024-04-23T18:11:35.056+0000] {local_task_job_runner.py:240} INFO - Task exited with return code 1
[2024-04-23T18:11:35.071+0000] {taskinstance.py:3482} INFO - 0 downstream tasks scheduled from follow-on schedule check
[2024-04-23T18:11:35.076+0000] {local_task_job_runner.py:222} INFO - ::endgroup::
