[2024-04-23T14:08:24.489+0000] {local_task_job_runner.py:120} INFO - ::group::Pre task execution logs
[2024-04-23T14:08:24.505+0000] {taskinstance.py:2073} INFO - Dependencies all met for dep_context=non-requeueable deps ti=<TaskInstance: daily_task_dag.task_2 manual__2024-04-23T14:08:22.326459+00:00 [queued]>
[2024-04-23T14:08:24.509+0000] {taskinstance.py:2073} INFO - Dependencies all met for dep_context=requeueable deps ti=<TaskInstance: daily_task_dag.task_2 manual__2024-04-23T14:08:22.326459+00:00 [queued]>
[2024-04-23T14:08:24.510+0000] {taskinstance.py:2303} INFO - Starting attempt 1 of 2
[2024-04-23T14:08:24.515+0000] {taskinstance.py:2327} INFO - Executing <Task(PythonOperator): task_2> on 2024-04-23 14:08:22.326459+00:00
[2024-04-23T14:08:24.521+0000] {standard_task_runner.py:90} INFO - Running: ['***', 'tasks', 'run', 'daily_task_dag', 'task_2', 'manual__2024-04-23T14:08:22.326459+00:00', '--job-id', '3', '--raw', '--subdir', 'DAGS_FOLDER/DataMLOps.py', '--cfg-path', '/tmp/tmptj8xcsph']
[2024-04-23T14:08:24.522+0000] {logging_mixin.py:188} WARNING - /home/***/.local/lib/python3.12/site-packages/***/task/task_runner/standard_task_runner.py:61 DeprecationWarning: This process (pid=366) is multi-threaded, use of fork() may lead to deadlocks in the child.
[2024-04-23T14:08:24.523+0000] {standard_task_runner.py:91} INFO - Job 3: Subtask task_2
[2024-04-23T14:08:24.523+0000] {standard_task_runner.py:63} INFO - Started process 377 to run task
[2024-04-23T14:08:24.547+0000] {task_command.py:426} INFO - Running <TaskInstance: daily_task_dag.task_2 manual__2024-04-23T14:08:22.326459+00:00 [running]> on host 830489e36216
[2024-04-23T14:08:24.875+0000] {taskinstance.py:2644} INFO - Exporting env vars: AIRFLOW_CTX_DAG_OWNER='***' AIRFLOW_CTX_DAG_ID='daily_task_dag' AIRFLOW_CTX_TASK_ID='task_2' AIRFLOW_CTX_EXECUTION_DATE='2024-04-23T14:08:22.326459+00:00' AIRFLOW_CTX_TRY_NUMBER='1' AIRFLOW_CTX_DAG_RUN_ID='manual__2024-04-23T14:08:22.326459+00:00'
[2024-04-23T14:08:24.875+0000] {taskinstance.py:430} INFO - ::endgroup::
[2024-04-23T14:08:24.895+0000] {taskinstance.py:441} INFO - ::group::Post task execution logs
[2024-04-23T14:08:24.896+0000] {taskinstance.py:2890} ERROR - Task failed with exception
Traceback (most recent call last):
  File "/home/airflow/.local/lib/python3.12/site-packages/airflow/models/taskinstance.py", line 465, in _execute_task
    result = _execute_callable(context=context, **execute_callable_kwargs)
             ^^^^^^^^^^^^^^^^^^^^^^^^^^^^^^^^^^^^^^^^^^^^^^^^^^^^^^^^^^^^^
  File "/home/airflow/.local/lib/python3.12/site-packages/airflow/models/taskinstance.py", line 432, in _execute_callable
    return execute_callable(context=context, **execute_callable_kwargs)
           ^^^^^^^^^^^^^^^^^^^^^^^^^^^^^^^^^^^^^^^^^^^^^^^^^^^^^^^^^^^^
  File "/home/airflow/.local/lib/python3.12/site-packages/airflow/models/baseoperator.py", line 400, in wrapper
    return func(self, *args, **kwargs)
           ^^^^^^^^^^^^^^^^^^^^^^^^^^^
  File "/home/airflow/.local/lib/python3.12/site-packages/airflow/operators/python.py", line 235, in execute
    return_value = self.execute_callable()
                   ^^^^^^^^^^^^^^^^^^^^^^^
  File "/home/airflow/.local/lib/python3.12/site-packages/airflow/operators/python.py", line 252, in execute_callable
    return self.python_callable(*self.op_args, **self.op_kwargs)
           ^^^^^^^^^^^^^^^^^^^^^^^^^^^^^^^^^^^^^^^^^^^^^^^^^^^^^
  File "/opt/airflow/dags/DataMLOps.py", line 16, in print_hello
    df = pd.read_csv('../data/iris.csv')
         ^^^^^^^^^^^^^^^^^^^^^^^^^^^^^^^
  File "/home/airflow/.local/lib/python3.12/site-packages/pandas/io/parsers/readers.py", line 948, in read_csv
    return _read(filepath_or_buffer, kwds)
           ^^^^^^^^^^^^^^^^^^^^^^^^^^^^^^^
  File "/home/airflow/.local/lib/python3.12/site-packages/pandas/io/parsers/readers.py", line 611, in _read
    parser = TextFileReader(filepath_or_buffer, **kwds)
             ^^^^^^^^^^^^^^^^^^^^^^^^^^^^^^^^^^^^^^^^^^
  File "/home/airflow/.local/lib/python3.12/site-packages/pandas/io/parsers/readers.py", line 1448, in __init__
    self._engine = self._make_engine(f, self.engine)
                   ^^^^^^^^^^^^^^^^^^^^^^^^^^^^^^^^^
  File "/home/airflow/.local/lib/python3.12/site-packages/pandas/io/parsers/readers.py", line 1705, in _make_engine
    self.handles = get_handle(
                   ^^^^^^^^^^^
  File "/home/airflow/.local/lib/python3.12/site-packages/pandas/io/common.py", line 863, in get_handle
    handle = open(
             ^^^^^
FileNotFoundError: [Errno 2] No such file or directory: '../data/iris.csv'
[2024-04-23T14:08:24.910+0000] {taskinstance.py:1205} INFO - Marking task as UP_FOR_RETRY. dag_id=daily_task_dag, task_id=task_2, execution_date=20240423T140822, start_date=20240423T140824, end_date=20240423T140824
[2024-04-23T14:08:24.919+0000] {standard_task_runner.py:110} ERROR - Failed to execute job 3 for task task_2 ([Errno 2] No such file or directory: '../data/iris.csv'; 377)
[2024-04-23T14:08:24.930+0000] {local_task_job_runner.py:240} INFO - Task exited with return code 1
[2024-04-23T14:08:24.946+0000] {taskinstance.py:3482} INFO - 0 downstream tasks scheduled from follow-on schedule check
[2024-04-23T14:08:24.948+0000] {local_task_job_runner.py:222} INFO - ::endgroup::
